<?xml version="1.0"?>
<robot name="tetrix">
    
    
    <link name="base_link">
        <visual>
            <geometry>
                <box size="0.288 0.288 0.06"/>
            </geometry>
            <origin xyz="0.0 0.0 0.03" rpy="0.0 0.0 0.0"/>
            <material name="white">
                <color rgba="1.0 1.0 1.0 1.0"/>
            </material>
        </visual>        
    </link>
    <link name="left_front_wheel">
        <visual>
            <geometry>
                <cylinder radius="0.05" length="0.025"/>
            </geometry>
            <origin xyz="0.0 0.0 0.0" rpy="1.5708 0.0 0.0"/>
            <material name="black">
                <color rgba="0.0 0.0 0.0 1.0"/>
            </material>
        </visual>
        <collision>
            <geometry>
                <cylinder radius="0.05" length="0.025"/>
            </geometry>
            <origin xyz="0.0 0.0 0.0" rpy="1.5708 0.0 0.0"/>
        </collision>
        <inertial>
            <mass value="10"/>
            <!--Calculate inertia matrix -->
            <inertia ixx="1.0" ixy="0.0" ixz="0.0" iyy="1.0" iyz="0.0" izz="1.0"/>
        </inertial>
    </link>
    <link name="right_front_wheel">
        <visual>
            <geometry>
                <cylinder radius="0.05" length="0.025"/>
            </geometry>
            <origin xyz="0.0 0.0 0.0" rpy="1.5708 0.0 0.0"/>
            <material name="black">
                <color rgba="0.0 0.0 0.0 1.0"/>
            </material>
        </visual>
        <collision>
            <geometry>
                <cylinder radius="0.05" length="0.025"/>
            </geometry>
            <origin xyz="0.0 0.0 0.0" rpy="1.5708 0.0 0.0"/>
        </collision>
        <inertial>
            <mass value="10"/>
            <!--Calculate inertia matrix -->
            <inertia ixx="1.0" ixy="0.0" ixz="0.0" iyy="1.0" iyz="0.0" izz="1.0"/>
        </inertial>
    </link>
    <link name="right_back_wheel">
        <visual>
            <geometry>
                <cylinder radius="0.05" length="0.025"/>
            </geometry>
            <origin xyz="0.0 0.0 0.0" rpy="1.5708 0.0 0.0"/>
            <material name="black">
                <color rgba="0.0 0.0 0.0 1.0"/>
            </material>
        </visual>
        <collision>
            <geometry>
                <cylinder radius="0.05" length="0.025"/>
            </geometry>
            <origin xyz="0.0 0.0 0.0" rpy="1.5708 0.0 0.0"/>
        </collision>
        <inertial>
            <mass value="10"/>
            <!--Calculate inertia matrix -->
            <inertia ixx="1.0" ixy="0.0" ixz="0.0" iyy="1.0" iyz="0.0" izz="1.0"/>
        </inertial>
    </link>
    <link name="left_back_wheel">
        <visual>
            <geometry>
                <cylinder radius="0.05" length="0.025"/>
            </geometry>
            <origin xyz="-0.0 0.0 0.0" rpy="1.5708 0.0 0.0"/>
            <material name="black">
                <color rgba="0.0 0.0 0.0 1.0"/>
            </material>
        </visual>
        <collision>
            <geometry>
                <cylinder radius="0.05" length="0.025"/>
            </geometry>
            <origin xyz="0.0 0.0 0.0" rpy="1.5708 0.0 0.0"/>
        </collision>
        <inertial>
            <mass value="10"/>
            <!--Calculate inertia matrix -->
            <inertia ixx="1.0" ixy="0.0" ixz="0.0" iyy="1.0" iyz="0.0" izz="1.0"/>
        </inertial>
    </link>
    <joint name="base_to_left_front_wheel" type="continuous">
        <parent link="base_link"/>
        <child link="left_front_wheel"/>
        <axis xyz="0.0 1 0.0"/>
        <origin xyz="0.100 -0.1665 0.0"/>   
    </joint>
    <joint name="base_to_right_front_wheel" type="continuous">
        <parent link="base_link"/>
        <child link="right_front_wheel"/>
        <axis xyz="0.0 1 0.0"/>
        <origin xyz="0.100 0.1665 0.0"/>   
    </joint>
    <joint name="base_to_right_back_wheel" type="continuous">
        <parent link="base_link"/>
        <child link="right_back_wheel"/>
        <axis xyz="0.0 1 0.0"/>
        <origin xyz="-0.100 0.1665 0.0"/>   
    </joint>
    <joint name="base_to_left_back_wheel" type="continuous">
        <parent link="base_link"/>
        <child link="left_back_wheel"/>
        <axis xyz="0.0 1 0.0"/>
        <origin xyz="-0.100 -0.1665 0.0"/>   
    </joint>    
</robot>